<?xml version="1.0"?>

<robot name="squirtle">
	
	<!-- <link name="base_station">
		<visual>
			<origin xyz="74 137 5" rpy="0 0 0" />
			<geometry>
				<box size="0.001 0.001 0.001" />
			</geometry>
		</visual>
	</link> -->
	
	<!-- base_footprint is a fictitious link(frame) that is on the ground right below base_link origin, navigation stack depends on this frame -->
	<link name="base_footprint">
		<visual>
			<origin xyz="0 0 0" rpy="0 0 0" />
			<geometry>
				<box size="0.001 0.001 0.001" />
			</geometry>
		</visual>
	</link>
	
	<!-- Links and Joints (i.e., the robot) -->
	<link name="base_link">
		<visual>
			<origin xyz="0 0 0" rpy="0 0 0" />
			<geometry>
				<mesh filename="package://squirtle_description/meshes/squirtle.dae"/>
			</geometry>
		</visual>
	</link>
	
	<joint name="base_footprint_base_link_joint" type="fixed">
		<parent link="base_footprint"/>
		<child link="base_link" />
		<origin xyz="0 0 0" rpy="0 0 0" />
	</joint>
	
 	<link name="left_motor">
		<visual>
			<origin xyz="0 0 0" rpy="0 0 0" />
			<geometry>
				<mesh filename="package://squirtle_description/meshes/left_motor.dae"/>
			</geometry>
		</visual>
	</link>
	
	<!-- left motor joint -->
	<joint name="left_motor_joint" type="continuous">
		<parent link="base_link"/>
		<child link="left_motor"/>
		<origin xyz="-1 0.56 0.31" rpy="0 0 0" />
		<axis xyz="0 0 1" />
	</joint>
        
	<link name="right_motor">
		<visual>
			<origin xyz="0 0 0" rpy="0 0 0" />
			<geometry>
				<mesh filename="package://squirtle_description/meshes/right_motor.dae"/>
			</geometry>
			
		</visual>
	</link>
	
	<!-- right motor joint -->
	<joint name="right_motor_joint" type="continuous">
		<parent link="base_link"/>
		<child link="right_motor"/>
		<origin xyz="-1 -0.56 0.31" rpy="0 0 0" />
		<axis xyz="0 0 1" />
	</joint>
	
	<!-- sonar -->
	<link name="sonar">
		<visual>
			<origin xyz="0 0 0" rpy="0 0 0" />
			<geometry>
				<box size="0.001 0.001 0.001" />
			</geometry>
		</visual>
	</link>
	
	<joint name="sonar_joint" type="fixed">
		<parent link="base_link"/>
		<child link="sonar"/>
		<origin xyz="1.01175 0.0 -0.12125" rpy="0.7853 0 1.57079" />
	</joint>
	
	<link name="cyclops">
		<visual>
			<origin xyz="0 0 0" rpy="0 0 0" />
			<geometry>
				<box size="0.001 0.001 0.001" />
			</geometry>
		</visual>
	</link>
	
	<!-- cyclops chemical sensor joint -->
	<joint name="cyclops_joint" type="fixed">
		<parent link="base_link"/>
		<child link="cyclops"/>
		<origin xyz="1.065 0.09 -0.175" rpy="0 0 0" />
	</joint>

	<link name="gps">
		<visual>
			<origin xyz="0 0 0" rpy="0 0 0" />
			<geometry>
				<mesh filename="package://squirtle_description/meshes/gps_antenna.dae"/>
			</geometry>
		</visual>
	</link>
	
	<joint name="gps_joint" type="fixed">
		<parent link="base_link"/>
		<child link="gps"/>
		<origin xyz="-0.24 -0.2 0.25" rpy="0 0 0" />
	</joint>
	
	<link name="imu">
		<visual>
			<origin xyz="0 0 0" rpy="0 0 0" />
			<geometry>
				<box size="0.001 0.001 0.001" />
			</geometry>
		</visual>
	</link>
	
	<!-- imu joint -->
	<joint name="imu_joint" type="fixed">
		<parent link="base_link"/>
		<child link="imu"/>
		<origin xyz="-0.50 0.0 0.25" rpy="0 0 0" />
	</joint>
        
</robot>

